Watching for file changes with StatReloader
Error: That port is already in use.
Watching for file changes with StatReloader
Not Found: /
[06/Nov/2024 02:37:00] "GET / HTTP/1.1" 404 3581
[06/Nov/2024 02:37:05] "GET /login/ HTTP/1.1" 200 4912
[06/Nov/2024 02:37:06] "GET /login/ HTTP/1.1" 200 4912
Watching for file changes with StatReloader
[06/Nov/2024 02:41:28] "GET /profile HTTP/1.1" 200 3614
[06/Nov/2024 02:41:42] "GET /login/ HTTP/1.1" 200 4912
[06/Nov/2024 02:41:43] "POST /login/ HTTP/1.1" 302 0
[06/Nov/2024 02:41:43] "GET /home/ HTTP/1.1" 200 4003
[06/Nov/2024 02:41:45] "GET /profile HTTP/1.1" 200 3991
/home/student/DCBS/users/views.py changed, reloading.
Performing system checks...

System check identified no issues (0 silenced).
November 06, 2024 - 02:39:05
Django version 5.1.2, using settings 'itapps.settings'
Starting development server at http://127.0.0.1:8000/
Quit the server with CONTROL-C.

Watching for file changes with StatReloader
/home/student/DCBS/users/views.py changed, reloading.
Performing system checks...

System check identified no issues (0 silenced).
November 06, 2024 - 02:42:12
Django version 5.1.2, using settings 'itapps.settings'
Starting development server at http://127.0.0.1:8000/
Quit the server with CONTROL-C.

Watching for file changes with StatReloader
/home/student/DCBS/users/views.py changed, reloading.
Performing system checks...

System check identified no issues (0 silenced).
November 06, 2024 - 02:42:14
Django version 5.1.2, using settings 'itapps.settings'
Starting development server at http://127.0.0.1:8000/
Quit the server with CONTROL-C.

Watching for file changes with StatReloader
/home/student/DCBS/users/views.py changed, reloading.
Performing system checks...

System check identified no issues (0 silenced).
November 06, 2024 - 02:42:47
Django version 5.1.2, using settings 'itapps.settings'
Starting development server at http://127.0.0.1:8000/
Quit the server with CONTROL-C.

Watching for file changes with StatReloader
/home/student/DCBS/users/views.py changed, reloading.
Performing system checks...

System check identified no issues (0 silenced).
November 06, 2024 - 02:42:50
Django version 5.1.2, using settings 'itapps.settings'
Starting development server at http://127.0.0.1:8000/
Quit the server with CONTROL-C.

Watching for file changes with StatReloader
/home/student/DCBS/users/views.py changed, reloading.
Performing system checks...

System check identified no issues (0 silenced).
November 06, 2024 - 02:42:54
Django version 5.1.2, using settings 'itapps.settings'
Starting development server at http://127.0.0.1:8000/
Quit the server with CONTROL-C.

Watching for file changes with StatReloader
/home/student/DCBS/itapps/settings.py changed, reloading.
Performing system checks...

System check identified no issues (0 silenced).
November 06, 2024 - 02:43:01
Django version 5.1.2, using settings 'itapps.settings'
Starting development server at http://127.0.0.1:8000/
Quit the server with CONTROL-C.

Watching for file changes with StatReloader
/home/student/DCBS/itapps/settings.py changed, reloading.
Performing system checks...

System check identified no issues (0 silenced).
November 06, 2024 - 02:43:24
Django version 5.1.2, using settings 'itapps.settings'
Starting development server at http://127.0.0.1:8000/
Quit the server with CONTROL-C.

Watching for file changes with StatReloader
/home/student/DCBS/itapps/settings.py changed, reloading.
Performing system checks...

System check identified no issues (0 silenced).
November 06, 2024 - 02:43:26
Django version 5.1.2, using settings 'itapps.settings'
Starting development server at http://127.0.0.1:8000/
Quit the server with CONTROL-C.

Watching for file changes with StatReloader
[06/Nov/2024 02:44:09] "GET /admin HTTP/1.1" 301 0
[06/Nov/2024 02:44:09] "GET /admin/ HTTP/1.1" 302 0
[06/Nov/2024 02:44:09] "GET /admin/login/?next=/admin/ HTTP/1.1" 200 3672
[06/Nov/2024 02:44:09] "GET /static/admin/css/base.css HTTP/1.1" 304 0
[06/Nov/2024 02:44:09] "GET /static/admin/css/dark_mode.css HTTP/1.1" 304 0
[06/Nov/2024 02:44:09] "GET /static/admin/js/theme.js HTTP/1.1" 304 0
[06/Nov/2024 02:44:09] "GET /static/admin/css/nav_sidebar.css HTTP/1.1" 304 0
[06/Nov/2024 02:44:09] "GET /static/admin/css/responsive.css HTTP/1.1" 304 0
[06/Nov/2024 02:44:09] "GET /static/admin/js/nav_sidebar.js HTTP/1.1" 304 0
[06/Nov/2024 02:44:09] "GET /static/admin/css/login.css HTTP/1.1" 304 0
[06/Nov/2024 02:44:20] "POST /admin/login/?next=/admin/ HTTP/1.1" 302 0
[06/Nov/2024 02:44:20] "GET /admin/ HTTP/1.1" 200 6730
[06/Nov/2024 02:44:20] "GET /static/admin/css/dashboard.css HTTP/1.1" 200 441
[06/Nov/2024 02:44:20] "GET /static/admin/img/icon-changelink.svg HTTP/1.1" 200 380
[06/Nov/2024 02:44:20] "GET /static/admin/img/icon-addlink.svg HTTP/1.1" 200 331
[06/Nov/2024 02:44:27] "GET /admin/itreporting/profile/add/ HTTP/1.1" 200 10378
[06/Nov/2024 02:44:27] "GET /static/admin/css/forms.css HTTP/1.1" 200 8794
[06/Nov/2024 02:44:27] "GET /static/admin/js/vendor/jquery/jquery.js HTTP/1.1" 304 0
[06/Nov/2024 02:44:27] "GET /static/admin/js/jquery.init.js HTTP/1.1" 304 0
[06/Nov/2024 02:44:27] "GET /static/admin/js/prepopulate_init.js HTTP/1.1" 200 586
[06/Nov/2024 02:44:27] "GET /static/admin/js/change_form.js HTTP/1.1" 200 606
[06/Nov/2024 02:44:27] "GET /static/admin/js/admin/RelatedObjectLookups.js HTTP/1.1" 304 0
[06/Nov/2024 02:44:27] "GET /static/admin/img/icon-viewlink.svg HTTP/1.1" 200 581
[06/Nov/2024 02:44:27] "GET /static/admin/js/core.js HTTP/1.1" 304 0
[06/Nov/2024 02:44:27] "GET /static/admin/js/actions.js HTTP/1.1" 304 0
[06/Nov/2024 02:44:27] "GET /admin/jsi18n/ HTTP/1.1" 200 3342
[06/Nov/2024 02:44:27] "GET /static/admin/js/urlify.js HTTP/1.1" 304 0
[06/Nov/2024 02:44:27] "GET /static/admin/js/prepopulate.js HTTP/1.1" 304 0
[06/Nov/2024 02:44:27] "GET /static/admin/js/vendor/xregexp/xregexp.js HTTP/1.1" 304 0
[06/Nov/2024 02:44:27] "GET /static/admin/css/widgets.css HTTP/1.1" 200 11564
[06/Nov/2024 02:46:51] "POST /admin/itreporting/profile/add/ HTTP/1.1" 302 0
[06/Nov/2024 02:46:51] "GET /admin/itreporting/profile/ HTTP/1.1" 200 9394
[06/Nov/2024 02:46:51] "GET /admin/jsi18n/ HTTP/1.1" 200 3342
[06/Nov/2024 02:46:51] "GET /static/admin/css/changelists.css HTTP/1.1" 304 0
[06/Nov/2024 02:46:51] "GET /static/admin/img/icon-yes.svg HTTP/1.1" 200 436
[06/Nov/2024 02:46:51] "GET /static/admin/img/tooltag-add.svg HTTP/1.1" 200 331
Not Found: /favicon.ico
/home/student/DCBS/itapps/settings.py changed, reloading.
Performing system checks...

System check identified no issues (0 silenced).
November 06, 2024 - 02:43:29
Django version 5.1.2, using settings 'itapps.settings'
Starting development server at http://127.0.0.1:8000/
Quit the server with CONTROL-C.

Watching for file changes with StatReloader
/home/student/DCBS/itapps/settings.py changed, reloading.
Performing system checks...

System check identified no issues (0 silenced).
November 06, 2024 - 02:49:57
Django version 5.1.2, using settings 'itapps.settings'
Starting development server at http://127.0.0.1:8000/
Quit the server with CONTROL-C.

Watching for file changes with StatReloader
/home/student/DCBS/itapps/urls.py changed, reloading.
Performing system checks...

System check identified no issues (0 silenced).
November 06, 2024 - 02:50:00
Django version 5.1.2, using settings 'itapps.settings'
Starting development server at http://127.0.0.1:8000/
Quit the server with CONTROL-C.

Watching for file changes with StatReloader
/home/student/DCBS/itapps/urls.py changed, reloading.
Performing system checks...

System check identified no issues (0 silenced).
November 06, 2024 - 02:50:21
Django version 5.1.2, using settings 'itapps.settings'
Starting development server at http://127.0.0.1:8000/
Quit the server with CONTROL-C.

Watching for file changes with StatReloader
/home/student/DCBS/itapps/urls.py changed, reloading.
Performing system checks...

System check identified no issues (0 silenced).
November 06, 2024 - 02:50:23
Django version 5.1.2, using settings 'itapps.settings'
Starting development server at http://127.0.0.1:8000/
Quit the server with CONTROL-C.

Watching for file changes with StatReloader
/home/student/DCBS/itapps/urls.py changed, reloading.
Performing system checks...

System check identified no issues (0 silenced).
November 06, 2024 - 02:51:07
Django version 5.1.2, using settings 'itapps.settings'
Starting development server at http://127.0.0.1:8000/
Quit the server with CONTROL-C.

Watching for file changes with StatReloader
[06/Nov/2024 02:51:53] "GET /admin/itreporting/profile/ HTTP/1.1" 200 9177
[06/Nov/2024 02:51:53] "GET /admin/jsi18n/ HTTP/1.1" 200 3342
Not Found: /favicon.ico
[06/Nov/2024 02:51:56] "GET /admin/itreporting/profile/1/change/ HTTP/1.1" 200 10760
[06/Nov/2024 02:51:56] "GET /admin/jsi18n/ HTTP/1.1" 200 3342
[06/Nov/2024 02:51:58] "GET /admin/itreporting/profile/1/delete/ HTTP/1.1" 200 7860
[06/Nov/2024 02:51:58] "GET /static/admin/js/cancel.js HTTP/1.1" 200 884
[06/Nov/2024 02:52:02] "POST /admin/itreporting/profile/1/delete/ HTTP/1.1" 302 0
[06/Nov/2024 02:52:02] "GET /admin/itreporting/profile/ HTTP/1.1" 200 8038
[06/Nov/2024 02:52:02] "GET /admin/jsi18n/ HTTP/1.1" 200 3342
Not Found: /favicon.ico
[06/Nov/2024 02:52:05] "GET /admin/itreporting/profile/add/ HTTP/1.1" 200 10378
[06/Nov/2024 02:52:05] "GET /admin/jsi18n/ HTTP/1.1" 200 3342
[06/Nov/2024 02:52:13] "POST /admin/itreporting/profile/add/ HTTP/1.1" 302 0
[06/Nov/2024 02:52:13] "GET /admin/itreporting/profile/ HTTP/1.1" 200 9394
[06/Nov/2024 02:52:13] "GET /admin/jsi18n/ HTTP/1.1" 200 3342
/home/student/DCBS/users/apps.py changed, reloading.
Performing system checks...

System check identified no issues (0 silenced).
November 06, 2024 - 02:51:09
Django version 5.1.2, using settings 'itapps.settings'
Starting development server at http://127.0.0.1:8000/
Quit the server with CONTROL-C.

Watching for file changes with StatReloader
Exception in thread django-main-thread:
Traceback (most recent call last):
  File "/usr/lib/python3.10/threading.py", line 1016, in _bootstrap_inner
    self.run()
  File "/usr/lib/python3.10/threading.py", line 953, in run
    self._target(*self._args, **self._kwargs)
  File "/home/student/.local/lib/python3.10/site-packages/django/utils/autoreload.py", line 64, in wrapper
    fn(*args, **kwargs)
  File "/home/student/.local/lib/python3.10/site-packages/django/core/management/commands/runserver.py", line 126, in inner_run
    autoreload.raise_last_exception()
  File "/home/student/.local/lib/python3.10/site-packages/django/utils/autoreload.py", line 87, in raise_last_exception
    raise _exception[1]
  File "/home/student/.local/lib/python3.10/site-packages/django/core/management/__init__.py", line 394, in execute
    autoreload.check_errors(django.setup)()
  File "/home/student/.local/lib/python3.10/site-packages/django/utils/autoreload.py", line 64, in wrapper
    fn(*args, **kwargs)
  File "/home/student/.local/lib/python3.10/site-packages/django/__init__.py", line 24, in setup
    apps.populate(settings.INSTALLED_APPS)
  File "/home/student/.local/lib/python3.10/site-packages/django/apps/registry.py", line 91, in populate
    app_config = AppConfig.create(entry)
  File "/home/student/.local/lib/python3.10/site-packages/django/apps/config.py", line 178, in create
    mod = import_module(mod_path)
  File "/usr/lib/python3.10/importlib/__init__.py", line 126, in import_module
    return _bootstrap._gcd_import(name[level:], package, level)
  File "<frozen importlib._bootstrap>", line 1050, in _gcd_import
  File "<frozen importlib._bootstrap>", line 1027, in _find_and_load
  File "<frozen importlib._bootstrap>", line 1006, in _find_and_load_unlocked
  File "<frozen importlib._bootstrap>", line 688, in _load_unlocked
  File "<frozen importlib._bootstrap_external>", line 879, in exec_module
  File "<frozen importlib._bootstrap_external>", line 1017, in get_code
  File "<frozen importlib._bootstrap_external>", line 947, in source_to_code
  File "<frozen importlib._bootstrap>", line 241, in _call_with_frames_removed
  File "/home/student/DCBS/users/apps.py", line 8
    content inside the UserConfig class:
            ^^^^^^
SyntaxError: invalid syntax
/home/student/DCBS/users/apps.py changed, reloading.
Watching for file changes with StatReloader
Exception in thread django-main-thread:
Traceback (most recent call last):
  File "/usr/lib/python3.10/threading.py", line 1016, in _bootstrap_inner
    self.run()
  File "/usr/lib/python3.10/threading.py", line 953, in run
    self._target(*self._args, **self._kwargs)
  File "/home/student/.local/lib/python3.10/site-packages/django/utils/autoreload.py", line 64, in wrapper
    fn(*args, **kwargs)
  File "/home/student/.local/lib/python3.10/site-packages/django/core/management/commands/runserver.py", line 126, in inner_run
    autoreload.raise_last_exception()
  File "/home/student/.local/lib/python3.10/site-packages/django/utils/autoreload.py", line 87, in raise_last_exception
    raise _exception[1]
  File "/home/student/.local/lib/python3.10/site-packages/django/core/management/__init__.py", line 394, in execute
    autoreload.check_errors(django.setup)()
  File "/home/student/.local/lib/python3.10/site-packages/django/utils/autoreload.py", line 64, in wrapper
    fn(*args, **kwargs)
  File "/home/student/.local/lib/python3.10/site-packages/django/__init__.py", line 24, in setup
    apps.populate(settings.INSTALLED_APPS)
  File "/home/student/.local/lib/python3.10/site-packages/django/apps/registry.py", line 91, in populate
    app_config = AppConfig.create(entry)
  File "/home/student/.local/lib/python3.10/site-packages/django/apps/config.py", line 178, in create
    mod = import_module(mod_path)
  File "/usr/lib/python3.10/importlib/__init__.py", line 126, in import_module
    return _bootstrap._gcd_import(name[level:], package, level)
  File "<frozen importlib._bootstrap>", line 1050, in _gcd_import
  File "<frozen importlib._bootstrap>", line 1027, in _find_and_load
  File "<frozen importlib._bootstrap>", line 1006, in _find_and_load_unlocked
  File "<frozen importlib._bootstrap>", line 688, in _load_unlocked
  File "<frozen importlib._bootstrap_external>", line 879, in exec_module
  File "<frozen importlib._bootstrap_external>", line 1017, in get_code
  File "<frozen importlib._bootstrap_external>", line 947, in source_to_code
  File "<frozen importlib._bootstrap>", line 241, in _call_with_frames_removed
  File "/home/student/DCBS/users/apps.py", line 8
    content inside the UserConfig class:
            ^^^^^^
SyntaxError: invalid syntax
/home/student/DCBS/users/apps.py changed, reloading.
Watching for file changes with StatReloader
Exception in thread django-main-thread:
Traceback (most recent call last):
  File "/usr/lib/python3.10/threading.py", line 1016, in _bootstrap_inner
    self.run()
  File "/usr/lib/python3.10/threading.py", line 953, in run
    self._target(*self._args, **self._kwargs)
  File "/home/student/.local/lib/python3.10/site-packages/django/utils/autoreload.py", line 64, in wrapper
    fn(*args, **kwargs)
  File "/home/student/.local/lib/python3.10/site-packages/django/core/management/commands/runserver.py", line 126, in inner_run
    autoreload.raise_last_exception()
  File "/home/student/.local/lib/python3.10/site-packages/django/utils/autoreload.py", line 87, in raise_last_exception
    raise _exception[1]
  File "/home/student/.local/lib/python3.10/site-packages/django/core/management/__init__.py", line 394, in execute
    autoreload.check_errors(django.setup)()
  File "/home/student/.local/lib/python3.10/site-packages/django/utils/autoreload.py", line 64, in wrapper
    fn(*args, **kwargs)
  File "/home/student/.local/lib/python3.10/site-packages/django/__init__.py", line 24, in setup
    apps.populate(settings.INSTALLED_APPS)
  File "/home/student/.local/lib/python3.10/site-packages/django/apps/registry.py", line 91, in populate
    app_config = AppConfig.create(entry)
  File "/home/student/.local/lib/python3.10/site-packages/django/apps/config.py", line 178, in create
    mod = import_module(mod_path)
  File "/usr/lib/python3.10/importlib/__init__.py", line 126, in import_module
    return _bootstrap._gcd_import(name[level:], package, level)
  File "<frozen importlib._bootstrap>", line 1050, in _gcd_import
  File "<frozen importlib._bootstrap>", line 1027, in _find_and_load
  File "<frozen importlib._bootstrap>", line 1006, in _find_and_load_unlocked
  File "<frozen importlib._bootstrap>", line 688, in _load_unlocked
  File "<frozen importlib._bootstrap_external>", line 879, in exec_module
  File "<frozen importlib._bootstrap_external>", line 1017, in get_code
  File "<frozen importlib._bootstrap_external>", line 947, in source_to_code
  File "<frozen importlib._bootstrap>", line 241, in _call_with_frames_removed
  File "/home/student/DCBS/users/apps.py", line 8
    content inside the UserConfig class:
            ^^^^^^
SyntaxError: invalid syntax
/home/student/DCBS/users/apps.py changed, reloading.
Watching for file changes with StatReloader
Exception in thread django-main-thread:
Traceback (most recent call last):
  File "/usr/lib/python3.10/threading.py", line 1016, in _bootstrap_inner
    self.run()
  File "/usr/lib/python3.10/threading.py", line 953, in run
    self._target(*self._args, **self._kwargs)
  File "/home/student/.local/lib/python3.10/site-packages/django/utils/autoreload.py", line 64, in wrapper
    fn(*args, **kwargs)
  File "/home/student/.local/lib/python3.10/site-packages/django/core/management/commands/runserver.py", line 126, in inner_run
    autoreload.raise_last_exception()
  File "/home/student/.local/lib/python3.10/site-packages/django/utils/autoreload.py", line 87, in raise_last_exception
    raise _exception[1]
  File "/home/student/.local/lib/python3.10/site-packages/django/core/management/__init__.py", line 394, in execute
    autoreload.check_errors(django.setup)()
  File "/home/student/.local/lib/python3.10/site-packages/django/utils/autoreload.py", line 64, in wrapper
    fn(*args, **kwargs)
  File "/home/student/.local/lib/python3.10/site-packages/django/__init__.py", line 24, in setup
    apps.populate(settings.INSTALLED_APPS)
  File "/home/student/.local/lib/python3.10/site-packages/django/apps/registry.py", line 91, in populate
    app_config = AppConfig.create(entry)
  File "/home/student/.local/lib/python3.10/site-packages/django/apps/config.py", line 178, in create
    mod = import_module(mod_path)
  File "/usr/lib/python3.10/importlib/__init__.py", line 126, in import_module
    return _bootstrap._gcd_import(name[level:], package, level)
  File "<frozen importlib._bootstrap>", line 1050, in _gcd_import
  File "<frozen importlib._bootstrap>", line 1027, in _find_and_load
  File "<frozen importlib._bootstrap>", line 1006, in _find_and_load_unlocked
  File "<frozen importlib._bootstrap>", line 688, in _load_unlocked
  File "<frozen importlib._bootstrap_external>", line 879, in exec_module
  File "<frozen importlib._bootstrap_external>", line 1017, in get_code
  File "<frozen importlib._bootstrap_external>", line 947, in source_to_code
  File "<frozen importlib._bootstrap>", line 241, in _call_with_frames_removed
  File "/home/student/DCBS/users/apps.py", line 8
    content inside the UserConfig class:
            ^^^^^^
SyntaxError: invalid syntax
/home/student/DCBS/users/apps.py changed, reloading.
Watching for file changes with StatReloader
Exception in thread django-main-thread:
Traceback (most recent call last):
  File "/usr/lib/python3.10/threading.py", line 1016, in _bootstrap_inner
    self.run()
  File "/usr/lib/python3.10/threading.py", line 953, in run
    self._target(*self._args, **self._kwargs)
  File "/home/student/.local/lib/python3.10/site-packages/django/utils/autoreload.py", line 64, in wrapper
    fn(*args, **kwargs)
  File "/home/student/.local/lib/python3.10/site-packages/django/core/management/commands/runserver.py", line 126, in inner_run
    autoreload.raise_last_exception()
  File "/home/student/.local/lib/python3.10/site-packages/django/utils/autoreload.py", line 87, in raise_last_exception
    raise _exception[1]
  File "/home/student/.local/lib/python3.10/site-packages/django/core/management/__init__.py", line 394, in execute
    autoreload.check_errors(django.setup)()
  File "/home/student/.local/lib/python3.10/site-packages/django/utils/autoreload.py", line 64, in wrapper
    fn(*args, **kwargs)
  File "/home/student/.local/lib/python3.10/site-packages/django/__init__.py", line 24, in setup
    apps.populate(settings.INSTALLED_APPS)
  File "/home/student/.local/lib/python3.10/site-packages/django/apps/registry.py", line 91, in populate
    app_config = AppConfig.create(entry)
  File "/home/student/.local/lib/python3.10/site-packages/django/apps/config.py", line 178, in create
    mod = import_module(mod_path)
  File "/usr/lib/python3.10/importlib/__init__.py", line 126, in import_module
    return _bootstrap._gcd_import(name[level:], package, level)
  File "<frozen importlib._bootstrap>", line 1050, in _gcd_import
  File "<frozen importlib._bootstrap>", line 1027, in _find_and_load
  File "<frozen importlib._bootstrap>", line 1006, in _find_and_load_unlocked
  File "<frozen importlib._bootstrap>", line 688, in _load_unlocked
  File "<frozen importlib._bootstrap_external>", line 879, in exec_module
  File "<frozen importlib._bootstrap_external>", line 1017, in get_code
  File "<frozen importlib._bootstrap_external>", line 947, in source_to_code
  File "<frozen importlib._bootstrap>", line 241, in _call_with_frames_removed
  File "/home/student/DCBS/users/apps.py", line 7
    content inside the UserConfig class:
            ^^^^^^
SyntaxError: invalid syntax
/home/student/DCBS/users/apps.py changed, reloading.
Watching for file changes with StatReloader
Exception in thread django-main-thread:
Traceback (most recent call last):
  File "/usr/lib/python3.10/threading.py", line 1016, in _bootstrap_inner
    self.run()
  File "/usr/lib/python3.10/threading.py", line 953, in run
    self._target(*self._args, **self._kwargs)
  File "/home/student/.local/lib/python3.10/site-packages/django/utils/autoreload.py", line 64, in wrapper
    fn(*args, **kwargs)
  File "/home/student/.local/lib/python3.10/site-packages/django/core/management/commands/runserver.py", line 126, in inner_run
    autoreload.raise_last_exception()
  File "/home/student/.local/lib/python3.10/site-packages/django/utils/autoreload.py", line 87, in raise_last_exception
    raise _exception[1]
  File "/home/student/.local/lib/python3.10/site-packages/django/core/management/__init__.py", line 394, in execute
    autoreload.check_errors(django.setup)()
  File "/home/student/.local/lib/python3.10/site-packages/django/utils/autoreload.py", line 64, in wrapper
    fn(*args, **kwargs)
  File "/home/student/.local/lib/python3.10/site-packages/django/__init__.py", line 24, in setup
    apps.populate(settings.INSTALLED_APPS)
  File "/home/student/.local/lib/python3.10/site-packages/django/apps/registry.py", line 124, in populate
    app_config.ready()
  File "/home/student/DCBS/users/apps.py", line 7, in ready
    def ready(self): from .signals import create_profile
  File "/home/student/DCBS/users/signals.py", line 4, in <module>
    from .models import Profile
ImportError: cannot import name 'Profile' from 'users.models' (/home/student/DCBS/users/models.py)
/home/student/DCBS/users/apps.py changed, reloading.
Watching for file changes with StatReloader
/home/student/DCBS/users/apps.py changed, reloading.
Performing system checks...

System check identified no issues (0 silenced).
November 06, 2024 - 02:57:11
Django version 5.1.2, using settings 'itapps.settings'
Starting development server at http://127.0.0.1:8000/
Quit the server with CONTROL-C.

Watching for file changes with StatReloader
/home/student/DCBS/users/models.py changed, reloading.
Performing system checks...

System check identified no issues (0 silenced).
November 06, 2024 - 02:57:13
Django version 5.1.2, using settings 'itapps.settings'
Starting development server at http://127.0.0.1:8000/
Quit the server with CONTROL-C.

Watching for file changes with StatReloader
/home/student/DCBS/users/models.py changed, reloading.
Performing system checks...

System check identified no issues (0 silenced).
November 06, 2024 - 02:57:39
Django version 5.1.2, using settings 'itapps.settings'
Starting development server at http://127.0.0.1:8000/
Quit the server with CONTROL-C.

Watching for file changes with StatReloader
/home/student/DCBS/users/models.py changed, reloading.
Performing system checks...

System check identified no issues (0 silenced).
November 06, 2024 - 02:57:45
Django version 5.1.2, using settings 'itapps.settings'
Starting development server at http://127.0.0.1:8000/
Quit the server with CONTROL-C.

Watching for file changes with StatReloader
[06/Nov/2024 03:00:26] "GET /register HTTP/1.1" 301 0
[06/Nov/2024 03:00:26] "GET /register/ HTTP/1.1" 200 7121
[06/Nov/2024 03:01:09] "POST /register/ HTTP/1.1" 302 0
[06/Nov/2024 03:01:09] "GET /login/ HTTP/1.1" 200 5379
[06/Nov/2024 03:01:18] "POST /login/ HTTP/1.1" 302 0
[06/Nov/2024 03:01:18] "GET /home/ HTTP/1.1" 200 4003
[06/Nov/2024 03:01:20] "GET /profile HTTP/1.1" 200 4397
[06/Nov/2024 03:01:20] "GET /media/profile_pics/default.png HTTP/1.1" 200 1414
/home/student/DCBS/users/forms.py changed, reloading.
Performing system checks...

System check identified no issues (0 silenced).
November 06, 2024 - 02:57:47
Django version 5.1.2, using settings 'itapps.settings'
Starting development server at http://127.0.0.1:8000/
Quit the server with CONTROL-C.

Watching for file changes with StatReloader
Exception in thread django-main-thread:
Traceback (most recent call last):
  File "/usr/lib/python3.10/threading.py", line 1016, in _bootstrap_inner
    self.run()
  File "/usr/lib/python3.10/threading.py", line 953, in run
    self._target(*self._args, **self._kwargs)
  File "/home/student/.local/lib/python3.10/site-packages/django/utils/autoreload.py", line 64, in wrapper
    fn(*args, **kwargs)
  File "/home/student/.local/lib/python3.10/site-packages/django/core/management/commands/runserver.py", line 134, in inner_run
    self.check(display_num_errors=True)
  File "/home/student/.local/lib/python3.10/site-packages/django/core/management/base.py", line 486, in check
    all_issues = checks.run_checks(
  File "/home/student/.local/lib/python3.10/site-packages/django/core/checks/registry.py", line 88, in run_checks
    new_errors = check(app_configs=app_configs, databases=databases)
  File "/home/student/.local/lib/python3.10/site-packages/django/core/checks/urls.py", line 136, in check_custom_error_handlers
    handler = resolver.resolve_error_handler(status_code)
  File "/home/student/.local/lib/python3.10/site-packages/django/urls/resolvers.py", line 732, in resolve_error_handler
    callback = getattr(self.urlconf_module, "handler%s" % view_type, None)
  File "/home/student/.local/lib/python3.10/site-packages/django/utils/functional.py", line 47, in __get__
    res = instance.__dict__[self.name] = self.func(instance)
  File "/home/student/.local/lib/python3.10/site-packages/django/urls/resolvers.py", line 711, in urlconf_module
    return import_module(self.urlconf_name)
  File "/usr/lib/python3.10/importlib/__init__.py", line 126, in import_module
    return _bootstrap._gcd_import(name[level:], package, level)
  File "<frozen importlib._bootstrap>", line 1050, in _gcd_import
  File "<frozen importlib._bootstrap>", line 1027, in _find_and_load
  File "<frozen importlib._bootstrap>", line 1006, in _find_and_load_unlocked
  File "<frozen importlib._bootstrap>", line 688, in _load_unlocked
  File "<frozen importlib._bootstrap_external>", line 883, in exec_module
  File "<frozen importlib._bootstrap>", line 241, in _call_with_frames_removed
  File "/home/student/DCBS/itapps/urls.py", line 19, in <module>
    from users import views
  File "/home/student/DCBS/users/views.py", line 4, in <module>
    from .forms import UserRegisterForm
  File "/home/student/DCBS/users/forms.py", line 4
    rom .models import Profile
                ^^^^^^
SyntaxError: invalid syntax
/home/student/DCBS/users/forms.py changed, reloading.
Performing system checks...

Watching for file changes with StatReloader
Exception in thread django-main-thread:
Traceback (most recent call last):
  File "/home/student/.local/lib/python3.10/site-packages/django/core/checks/urls.py", line 136, in check_custom_error_handlers
    handler = resolver.resolve_error_handler(status_code)
  File "/home/student/.local/lib/python3.10/site-packages/django/urls/resolvers.py", line 732, in resolve_error_handler
    callback = getattr(self.urlconf_module, "handler%s" % view_type, None)
  File "/home/student/.local/lib/python3.10/site-packages/django/utils/functional.py", line 47, in __get__
    res = instance.__dict__[self.name] = self.func(instance)
  File "/home/student/.local/lib/python3.10/site-packages/django/urls/resolvers.py", line 711, in urlconf_module
    return import_module(self.urlconf_name)
  File "/usr/lib/python3.10/importlib/__init__.py", line 126, in import_module
    return _bootstrap._gcd_import(name[level:], package, level)
  File "<frozen importlib._bootstrap>", line 1050, in _gcd_import
  File "<frozen importlib._bootstrap>", line 1027, in _find_and_load
  File "<frozen importlib._bootstrap>", line 1006, in _find_and_load_unlocked
  File "<frozen importlib._bootstrap>", line 688, in _load_unlocked
  File "<frozen importlib._bootstrap_external>", line 883, in exec_module
  File "<frozen importlib._bootstrap>", line 241, in _call_with_frames_removed
  File "/home/student/DCBS/itapps/urls.py", line 19, in <module>
    from users import views
  File "/home/student/DCBS/users/views.py", line 4, in <module>
    from .forms import UserRegisterForm
  File "/home/student/DCBS/users/forms.py", line 4, in <module>
    from .models import Profile
ImportError: cannot import name 'Profile' from 'users.models' (/home/student/DCBS/users/models.py)

During handling of the above exception, another exception occurred:

Traceback (most recent call last):
  File "/usr/lib/python3.10/threading.py", line 1016, in _bootstrap_inner
    self.run()
  File "/usr/lib/python3.10/threading.py", line 953, in run
    self._target(*self._args, **self._kwargs)
  File "/home/student/.local/lib/python3.10/site-packages/django/utils/autoreload.py", line 64, in wrapper
    fn(*args, **kwargs)
  File "/home/student/.local/lib/python3.10/site-packages/django/core/management/commands/runserver.py", line 134, in inner_run
    self.check(display_num_errors=True)
  File "/home/student/.local/lib/python3.10/site-packages/django/core/management/base.py", line 486, in check
    all_issues = checks.run_checks(
  File "/home/student/.local/lib/python3.10/site-packages/django/core/checks/registry.py", line 88, in run_checks
    new_errors = check(app_configs=app_configs, databases=databases)
  File "/home/student/.local/lib/python3.10/site-packages/django/core/checks/urls.py", line 138, in check_custom_error_handlers
    path = getattr(resolver.urlconf_module, "handler%s" % status_code)
  File "/home/student/.local/lib/python3.10/site-packages/django/utils/functional.py", line 47, in __get__
    res = instance.__dict__[self.name] = self.func(instance)
  File "/home/student/.local/lib/python3.10/site-packages/django/urls/resolvers.py", line 711, in urlconf_module
    return import_module(self.urlconf_name)
  File "/usr/lib/python3.10/importlib/__init__.py", line 126, in import_module
    return _bootstrap._gcd_import(name[level:], package, level)
  File "<frozen importlib._bootstrap>", line 1050, in _gcd_import
  File "<frozen importlib._bootstrap>", line 1027, in _find_and_load
  File "<frozen importlib._bootstrap>", line 1006, in _find_and_load_unlocked
  File "<frozen importlib._bootstrap>", line 688, in _load_unlocked
  File "<frozen importlib._bootstrap_external>", line 883, in exec_module
  File "<frozen importlib._bootstrap>", line 241, in _call_with_frames_removed
  File "/home/student/DCBS/itapps/urls.py", line 19, in <module>
    from users import views
  File "/home/student/DCBS/users/views.py", line 4, in <module>
    from .forms import UserRegisterForm
  File "/home/student/DCBS/users/forms.py", line 4, in <module>
    from .models import Profile
ImportError: cannot import name 'Profile' from 'users.models' (/home/student/DCBS/users/models.py)
/home/student/DCBS/users/forms.py changed, reloading.
Performing system checks...

Watching for file changes with StatReloader
Exception in thread django-main-thread:
Traceback (most recent call last):
  File "/home/student/.local/lib/python3.10/site-packages/django/core/checks/urls.py", line 136, in check_custom_error_handlers
    handler = resolver.resolve_error_handler(status_code)
  File "/home/student/.local/lib/python3.10/site-packages/django/urls/resolvers.py", line 732, in resolve_error_handler
    callback = getattr(self.urlconf_module, "handler%s" % view_type, None)
  File "/home/student/.local/lib/python3.10/site-packages/django/utils/functional.py", line 47, in __get__
    res = instance.__dict__[self.name] = self.func(instance)
  File "/home/student/.local/lib/python3.10/site-packages/django/urls/resolvers.py", line 711, in urlconf_module
    return import_module(self.urlconf_name)
  File "/usr/lib/python3.10/importlib/__init__.py", line 126, in import_module
    return _bootstrap._gcd_import(name[level:], package, level)
  File "<frozen importlib._bootstrap>", line 1050, in _gcd_import
  File "<frozen importlib._bootstrap>", line 1027, in _find_and_load
  File "<frozen importlib._bootstrap>", line 1006, in _find_and_load_unlocked
  File "<frozen importlib._bootstrap>", line 688, in _load_unlocked
  File "<frozen importlib._bootstrap_external>", line 883, in exec_module
  File "<frozen importlib._bootstrap>", line 241, in _call_with_frames_removed
  File "/home/student/DCBS/itapps/urls.py", line 19, in <module>
    from users import views
  File "/home/student/DCBS/users/views.py", line 4, in <module>
    from .forms import UserRegisterForm
  File "/home/student/DCBS/users/forms.py", line 4, in <module>
    from .models import Profile
ImportError: cannot import name 'Profile' from 'users.models' (/home/student/DCBS/users/models.py)

During handling of the above exception, another exception occurred:

Traceback (most recent call last):
  File "/usr/lib/python3.10/threading.py", line 1016, in _bootstrap_inner
    self.run()
  File "/usr/lib/python3.10/threading.py", line 953, in run
    self._target(*self._args, **self._kwargs)
  File "/home/student/.local/lib/python3.10/site-packages/django/utils/autoreload.py", line 64, in wrapper
    fn(*args, **kwargs)
  File "/home/student/.local/lib/python3.10/site-packages/django/core/management/commands/runserver.py", line 134, in inner_run
    self.check(display_num_errors=True)
  File "/home/student/.local/lib/python3.10/site-packages/django/core/management/base.py", line 486, in check
    all_issues = checks.run_checks(
  File "/home/student/.local/lib/python3.10/site-packages/django/core/checks/registry.py", line 88, in run_checks
    new_errors = check(app_configs=app_configs, databases=databases)
  File "/home/student/.local/lib/python3.10/site-packages/django/core/checks/urls.py", line 138, in check_custom_error_handlers
    path = getattr(resolver.urlconf_module, "handler%s" % status_code)
  File "/home/student/.local/lib/python3.10/site-packages/django/utils/functional.py", line 47, in __get__
    res = instance.__dict__[self.name] = self.func(instance)
  File "/home/student/.local/lib/python3.10/site-packages/django/urls/resolvers.py", line 711, in urlconf_module
    return import_module(self.urlconf_name)
  File "/usr/lib/python3.10/importlib/__init__.py", line 126, in import_module
    return _bootstrap._gcd_import(name[level:], package, level)
  File "<frozen importlib._bootstrap>", line 1050, in _gcd_import
  File "<frozen importlib._bootstrap>", line 1027, in _find_and_load
  File "<frozen importlib._bootstrap>", line 1006, in _find_and_load_unlocked
  File "<frozen importlib._bootstrap>", line 688, in _load_unlocked
  File "<frozen importlib._bootstrap_external>", line 883, in exec_module
  File "<frozen importlib._bootstrap>", line 241, in _call_with_frames_removed
  File "/home/student/DCBS/itapps/urls.py", line 19, in <module>
    from users import views
  File "/home/student/DCBS/users/views.py", line 4, in <module>
    from .forms import UserRegisterForm
  File "/home/student/DCBS/users/forms.py", line 4, in <module>
    from .models import Profile
ImportError: cannot import name 'Profile' from 'users.models' (/home/student/DCBS/users/models.py)
/home/student/DCBS/users/forms.py changed, reloading.
Performing system checks...

Watching for file changes with StatReloader
Exception in thread django-main-thread:
Traceback (most recent call last):
  File "/home/student/.local/lib/python3.10/site-packages/django/core/checks/urls.py", line 136, in check_custom_error_handlers
    handler = resolver.resolve_error_handler(status_code)
  File "/home/student/.local/lib/python3.10/site-packages/django/urls/resolvers.py", line 732, in resolve_error_handler
    callback = getattr(self.urlconf_module, "handler%s" % view_type, None)
  File "/home/student/.local/lib/python3.10/site-packages/django/utils/functional.py", line 47, in __get__
    res = instance.__dict__[self.name] = self.func(instance)
  File "/home/student/.local/lib/python3.10/site-packages/django/urls/resolvers.py", line 711, in urlconf_module
    return import_module(self.urlconf_name)
  File "/usr/lib/python3.10/importlib/__init__.py", line 126, in import_module
    return _bootstrap._gcd_import(name[level:], package, level)
  File "<frozen importlib._bootstrap>", line 1050, in _gcd_import
  File "<frozen importlib._bootstrap>", line 1027, in _find_and_load
  File "<frozen importlib._bootstrap>", line 1006, in _find_and_load_unlocked
  File "<frozen importlib._bootstrap>", line 688, in _load_unlocked
  File "<frozen importlib._bootstrap_external>", line 883, in exec_module
  File "<frozen importlib._bootstrap>", line 241, in _call_with_frames_removed
  File "/home/student/DCBS/itapps/urls.py", line 19, in <module>
    from users import views
  File "/home/student/DCBS/users/views.py", line 4, in <module>
    from .forms import UserRegisterForm
  File "/home/student/DCBS/users/forms.py", line 4, in <module>
    from .models import Profile
ImportError: cannot import name 'Profile' from 'users.models' (/home/student/DCBS/users/models.py)

During handling of the above exception, another exception occurred:

Traceback (most recent call last):
  File "/usr/lib/python3.10/threading.py", line 1016, in _bootstrap_inner
    self.run()
  File "/usr/lib/python3.10/threading.py", line 953, in run
    self._target(*self._args, **self._kwargs)
  File "/home/student/.local/lib/python3.10/site-packages/django/utils/autoreload.py", line 64, in wrapper
    fn(*args, **kwargs)
  File "/home/student/.local/lib/python3.10/site-packages/django/core/management/commands/runserver.py", line 134, in inner_run
    self.check(display_num_errors=True)
  File "/home/student/.local/lib/python3.10/site-packages/django/core/management/base.py", line 486, in check
    all_issues = checks.run_checks(
  File "/home/student/.local/lib/python3.10/site-packages/django/core/checks/registry.py", line 88, in run_checks
    new_errors = check(app_configs=app_configs, databases=databases)
  File "/home/student/.local/lib/python3.10/site-packages/django/core/checks/urls.py", line 138, in check_custom_error_handlers
    path = getattr(resolver.urlconf_module, "handler%s" % status_code)
  File "/home/student/.local/lib/python3.10/site-packages/django/utils/functional.py", line 47, in __get__
    res = instance.__dict__[self.name] = self.func(instance)
  File "/home/student/.local/lib/python3.10/site-packages/django/urls/resolvers.py", line 711, in urlconf_module
    return import_module(self.urlconf_name)
  File "/usr/lib/python3.10/importlib/__init__.py", line 126, in import_module
    return _bootstrap._gcd_import(name[level:], package, level)
  File "<frozen importlib._bootstrap>", line 1050, in _gcd_import
  File "<frozen importlib._bootstrap>", line 1027, in _find_and_load
  File "<frozen importlib._bootstrap>", line 1006, in _find_and_load_unlocked
  File "<frozen importlib._bootstrap>", line 688, in _load_unlocked
  File "<frozen importlib._bootstrap_external>", line 883, in exec_module
  File "<frozen importlib._bootstrap>", line 241, in _call_with_frames_removed
  File "/home/student/DCBS/itapps/urls.py", line 19, in <module>
    from users import views
  File "/home/student/DCBS/users/views.py", line 4, in <module>
    from .forms import UserRegisterForm
  File "/home/student/DCBS/users/forms.py", line 4, in <module>
    from .models import Profile
ImportError: cannot import name 'Profile' from 'users.models' (/home/student/DCBS/users/models.py)
/home/student/DCBS/users/forms.py changed, reloading.
Performing system checks...

Watching for file changes with StatReloader
Exception in thread django-main-thread:
Traceback (most recent call last):
  File "/usr/lib/python3.10/threading.py", line 1016, in _bootstrap_inner
    self.run()
  File "/usr/lib/python3.10/threading.py", line 953, in run
    self._target(*self._args, **self._kwargs)
  File "/home/student/.local/lib/python3.10/site-packages/django/utils/autoreload.py", line 64, in wrapper
    fn(*args, **kwargs)
  File "/home/student/.local/lib/python3.10/site-packages/django/core/management/commands/runserver.py", line 134, in inner_run
    self.check(display_num_errors=True)
  File "/home/student/.local/lib/python3.10/site-packages/django/core/management/base.py", line 486, in check
    all_issues = checks.run_checks(
  File "/home/student/.local/lib/python3.10/site-packages/django/core/checks/registry.py", line 88, in run_checks
    new_errors = check(app_configs=app_configs, databases=databases)
  File "/home/student/.local/lib/python3.10/site-packages/django/core/checks/urls.py", line 136, in check_custom_error_handlers
    handler = resolver.resolve_error_handler(status_code)
  File "/home/student/.local/lib/python3.10/site-packages/django/urls/resolvers.py", line 732, in resolve_error_handler
    callback = getattr(self.urlconf_module, "handler%s" % view_type, None)
  File "/home/student/.local/lib/python3.10/site-packages/django/utils/functional.py", line 47, in __get__
    res = instance.__dict__[self.name] = self.func(instance)
  File "/home/student/.local/lib/python3.10/site-packages/django/urls/resolvers.py", line 711, in urlconf_module
    return import_module(self.urlconf_name)
  File "/usr/lib/python3.10/importlib/__init__.py", line 126, in import_module
    return _bootstrap._gcd_import(name[level:], package, level)
  File "<frozen importlib._bootstrap>", line 1050, in _gcd_import
  File "<frozen importlib._bootstrap>", line 1027, in _find_and_load
  File "<frozen importlib._bootstrap>", line 1006, in _find_and_load_unlocked
  File "<frozen importlib._bootstrap>", line 688, in _load_unlocked
  File "<frozen importlib._bootstrap_external>", line 883, in exec_module
  File "<frozen importlib._bootstrap>", line 241, in _call_with_frames_removed
  File "/home/student/DCBS/itapps/urls.py", line 19, in <module>
    from users import views
  File "/home/student/DCBS/users/views.py", line 4, in <module>
    from .forms import UserRegisterForm
  File "/home/student/DCBS/users/forms.py", line 15
    model = User
    ^
IndentationError: expected an indented block after class definition on line 14
/home/student/DCBS/users/forms.py changed, reloading.
Performing system checks...

Watching for file changes with StatReloader
Exception in thread django-main-thread:
Traceback (most recent call last):
  File "/usr/lib/python3.10/threading.py", line 1016, in _bootstrap_inner
    self.run()
  File "/usr/lib/python3.10/threading.py", line 953, in run
    self._target(*self._args, **self._kwargs)
  File "/home/student/.local/lib/python3.10/site-packages/django/utils/autoreload.py", line 64, in wrapper
    fn(*args, **kwargs)
  File "/home/student/.local/lib/python3.10/site-packages/django/core/management/commands/runserver.py", line 134, in inner_run
    self.check(display_num_errors=True)
  File "/home/student/.local/lib/python3.10/site-packages/django/core/management/base.py", line 486, in check
    all_issues = checks.run_checks(
  File "/home/student/.local/lib/python3.10/site-packages/django/core/checks/registry.py", line 88, in run_checks
    new_errors = check(app_configs=app_configs, databases=databases)
  File "/home/student/.local/lib/python3.10/site-packages/django/core/checks/urls.py", line 136, in check_custom_error_handlers
    handler = resolver.resolve_error_handler(status_code)
  File "/home/student/.local/lib/python3.10/site-packages/django/urls/resolvers.py", line 732, in resolve_error_handler
    callback = getattr(self.urlconf_module, "handler%s" % view_type, None)
  File "/home/student/.local/lib/python3.10/site-packages/django/utils/functional.py", line 47, in __get__
    res = instance.__dict__[self.name] = self.func(instance)
  File "/home/student/.local/lib/python3.10/site-packages/django/urls/resolvers.py", line 711, in urlconf_module
    return import_module(self.urlconf_name)
  File "/usr/lib/python3.10/importlib/__init__.py", line 126, in import_module
    return _bootstrap._gcd_import(name[level:], package, level)
  File "<frozen importlib._bootstrap>", line 1050, in _gcd_import
  File "<frozen importlib._bootstrap>", line 1027, in _find_and_load
  File "<frozen importlib._bootstrap>", line 1006, in _find_and_load_unlocked
  File "<frozen importlib._bootstrap>", line 688, in _load_unlocked
  File "<frozen importlib._bootstrap_external>", line 883, in exec_module
  File "<frozen importlib._bootstrap>", line 241, in _call_with_frames_removed
  File "/home/student/DCBS/itapps/urls.py", line 19, in <module>
    from users import views
  File "/home/student/DCBS/users/views.py", line 4, in <module>
    from .forms import UserRegisterForm
  File "/home/student/DCBS/users/forms.py", line 18
    class Meta:
    ^
IndentationError: expected an indented block after class definition on line 17
/home/student/DCBS/users/forms.py changed, reloading.
Performing system checks...

Watching for file changes with StatReloader
Exception in thread django-main-thread:
Traceback (most recent call last):
  File "/usr/lib/python3.10/threading.py", line 1016, in _bootstrap_inner
    self.run()
  File "/usr/lib/python3.10/threading.py", line 953, in run
    self._target(*self._args, **self._kwargs)
  File "/home/student/.local/lib/python3.10/site-packages/django/utils/autoreload.py", line 64, in wrapper
    fn(*args, **kwargs)
  File "/home/student/.local/lib/python3.10/site-packages/django/core/management/commands/runserver.py", line 134, in inner_run
    self.check(display_num_errors=True)
  File "/home/student/.local/lib/python3.10/site-packages/django/core/management/base.py", line 486, in check
    all_issues = checks.run_checks(
  File "/home/student/.local/lib/python3.10/site-packages/django/core/checks/registry.py", line 88, in run_checks
    new_errors = check(app_configs=app_configs, databases=databases)
  File "/home/student/.local/lib/python3.10/site-packages/django/core/checks/urls.py", line 136, in check_custom_error_handlers
    handler = resolver.resolve_error_handler(status_code)
  File "/home/student/.local/lib/python3.10/site-packages/django/urls/resolvers.py", line 732, in resolve_error_handler
    callback = getattr(self.urlconf_module, "handler%s" % view_type, None)
  File "/home/student/.local/lib/python3.10/site-packages/django/utils/functional.py", line 47, in __get__
    res = instance.__dict__[self.name] = self.func(instance)
  File "/home/student/.local/lib/python3.10/site-packages/django/urls/resolvers.py", line 711, in urlconf_module
    return import_module(self.urlconf_name)
  File "/usr/lib/python3.10/importlib/__init__.py", line 126, in import_module
    return _bootstrap._gcd_import(name[level:], package, level)
  File "<frozen importlib._bootstrap>", line 1050, in _gcd_import
  File "<frozen importlib._bootstrap>", line 1027, in _find_and_load
  File "<frozen importlib._bootstrap>", line 1006, in _find_and_load_unlocked
  File "<frozen importlib._bootstrap>", line 688, in _load_unlocked
  File "<frozen importlib._bootstrap_external>", line 883, in exec_module
  File "<frozen importlib._bootstrap>", line 241, in _call_with_frames_removed
  File "/home/student/DCBS/itapps/urls.py", line 19, in <module>
    from users import views
  File "/home/student/DCBS/users/views.py", line 4, in <module>
    from .forms import UserRegisterForm
  File "/home/student/DCBS/users/forms.py", line 19
    model = Profile
IndentationError: expected an indented block after class definition on line 18
/home/student/DCBS/users/forms.py changed, reloading.
Performing system checks...

Watching for file changes with StatReloader
Exception in thread django-main-thread:
Traceback (most recent call last):
  File "/home/student/.local/lib/python3.10/site-packages/django/core/checks/urls.py", line 136, in check_custom_error_handlers
    handler = resolver.resolve_error_handler(status_code)
  File "/home/student/.local/lib/python3.10/site-packages/django/urls/resolvers.py", line 732, in resolve_error_handler
    callback = getattr(self.urlconf_module, "handler%s" % view_type, None)
  File "/home/student/.local/lib/python3.10/site-packages/django/utils/functional.py", line 47, in __get__
    res = instance.__dict__[self.name] = self.func(instance)
  File "/home/student/.local/lib/python3.10/site-packages/django/urls/resolvers.py", line 711, in urlconf_module
    return import_module(self.urlconf_name)
  File "/usr/lib/python3.10/importlib/__init__.py", line 126, in import_module
    return _bootstrap._gcd_import(name[level:], package, level)
  File "<frozen importlib._bootstrap>", line 1050, in _gcd_import
  File "<frozen importlib._bootstrap>", line 1027, in _find_and_load
  File "<frozen importlib._bootstrap>", line 1006, in _find_and_load_unlocked
  File "<frozen importlib._bootstrap>", line 688, in _load_unlocked
  File "<frozen importlib._bootstrap_external>", line 883, in exec_module
  File "<frozen importlib._bootstrap>", line 241, in _call_with_frames_removed
  File "/home/student/DCBS/itapps/urls.py", line 19, in <module>
    from users import views
  File "/home/student/DCBS/users/views.py", line 4, in <module>
    from .forms import UserRegisterForm
  File "/home/student/DCBS/users/forms.py", line 4, in <module>
    from .models import Profile
ImportError: cannot import name 'Profile' from 'users.models' (/home/student/DCBS/users/models.py)

During handling of the above exception, another exception occurred:

Traceback (most recent call last):
  File "/usr/lib/python3.10/threading.py", line 1016, in _bootstrap_inner
    self.run()
  File "/usr/lib/python3.10/threading.py", line 953, in run
    self._target(*self._args, **self._kwargs)
  File "/home/student/.local/lib/python3.10/site-packages/django/utils/autoreload.py", line 64, in wrapper
    fn(*args, **kwargs)
  File "/home/student/.local/lib/python3.10/site-packages/django/core/management/commands/runserver.py", line 134, in inner_run
    self.check(display_num_errors=True)
  File "/home/student/.local/lib/python3.10/site-packages/django/core/management/base.py", line 486, in check
    all_issues = checks.run_checks(
  File "/home/student/.local/lib/python3.10/site-packages/django/core/checks/registry.py", line 88, in run_checks
    new_errors = check(app_configs=app_configs, databases=databases)
  File "/home/student/.local/lib/python3.10/site-packages/django/core/checks/urls.py", line 138, in check_custom_error_handlers
    path = getattr(resolver.urlconf_module, "handler%s" % status_code)
  File "/home/student/.local/lib/python3.10/site-packages/django/utils/functional.py", line 47, in __get__
    res = instance.__dict__[self.name] = self.func(instance)
  File "/home/student/.local/lib/python3.10/site-packages/django/urls/resolvers.py", line 711, in urlconf_module
    return import_module(self.urlconf_name)
  File "/usr/lib/python3.10/importlib/__init__.py", line 126, in import_module
    return _bootstrap._gcd_import(name[level:], package, level)
  File "<frozen importlib._bootstrap>", line 1050, in _gcd_import
  File "<frozen importlib._bootstrap>", line 1027, in _find_and_load
  File "<frozen importlib._bootstrap>", line 1006, in _find_and_load_unlocked
  File "<frozen importlib._bootstrap>", line 688, in _load_unlocked
  File "<frozen importlib._bootstrap_external>", line 883, in exec_module
  File "<frozen importlib._bootstrap>", line 241, in _call_with_frames_removed
  File "/home/student/DCBS/itapps/urls.py", line 19, in <module>
    from users import views
  File "/home/student/DCBS/users/views.py", line 4, in <module>
    from .forms import UserRegisterForm
  File "/home/student/DCBS/users/forms.py", line 4, in <module>
    from .models import Profile
ImportError: cannot import name 'Profile' from 'users.models' (/home/student/DCBS/users/models.py)
/home/student/DCBS/users/forms.py changed, reloading.
Performing system checks...

Watching for file changes with StatReloader
Exception in thread django-main-thread:
Traceback (most recent call last):
  File "/home/student/.local/lib/python3.10/site-packages/django/core/checks/urls.py", line 136, in check_custom_error_handlers
    handler = resolver.resolve_error_handler(status_code)
  File "/home/student/.local/lib/python3.10/site-packages/django/urls/resolvers.py", line 732, in resolve_error_handler
    callback = getattr(self.urlconf_module, "handler%s" % view_type, None)
  File "/home/student/.local/lib/python3.10/site-packages/django/utils/functional.py", line 47, in __get__
    res = instance.__dict__[self.name] = self.func(instance)
  File "/home/student/.local/lib/python3.10/site-packages/django/urls/resolvers.py", line 711, in urlconf_module
    return import_module(self.urlconf_name)
  File "/usr/lib/python3.10/importlib/__init__.py", line 126, in import_module
    return _bootstrap._gcd_import(name[level:], package, level)
  File "<frozen importlib._bootstrap>", line 1050, in _gcd_import
  File "<frozen importlib._bootstrap>", line 1027, in _find_and_load
  File "<frozen importlib._bootstrap>", line 1006, in _find_and_load_unlocked
  File "<frozen importlib._bootstrap>", line 688, in _load_unlocked
  File "<frozen importlib._bootstrap_external>", line 883, in exec_module
  File "<frozen importlib._bootstrap>", line 241, in _call_with_frames_removed
  File "/home/student/DCBS/itapps/urls.py", line 19, in <module>
    from users import views
  File "/home/student/DCBS/users/views.py", line 4, in <module>
    from .forms import UserRegisterForm
  File "/home/student/DCBS/users/forms.py", line 4, in <module>
    from .models import Profile
ImportError: cannot import name 'Profile' from 'users.models' (/home/student/DCBS/users/models.py)

During handling of the above exception, another exception occurred:

Traceback (most recent call last):
  File "/usr/lib/python3.10/threading.py", line 1016, in _bootstrap_inner
    self.run()
  File "/usr/lib/python3.10/threading.py", line 953, in run
    self._target(*self._args, **self._kwargs)
  File "/home/student/.local/lib/python3.10/site-packages/django/utils/autoreload.py", line 64, in wrapper
    fn(*args, **kwargs)
  File "/home/student/.local/lib/python3.10/site-packages/django/core/management/commands/runserver.py", line 134, in inner_run
    self.check(display_num_errors=True)
  File "/home/student/.local/lib/python3.10/site-packages/django/core/management/base.py", line 486, in check
    all_issues = checks.run_checks(
  File "/home/student/.local/lib/python3.10/site-packages/django/core/checks/registry.py", line 88, in run_checks
    new_errors = check(app_configs=app_configs, databases=databases)
  File "/home/student/.local/lib/python3.10/site-packages/django/core/checks/urls.py", line 138, in check_custom_error_handlers
    path = getattr(resolver.urlconf_module, "handler%s" % status_code)
  File "/home/student/.local/lib/python3.10/site-packages/django/utils/functional.py", line 47, in __get__
    res = instance.__dict__[self.name] = self.func(instance)
  File "/home/student/.local/lib/python3.10/site-packages/django/urls/resolvers.py", line 711, in urlconf_module
    return import_module(self.urlconf_name)
  File "/usr/lib/python3.10/importlib/__init__.py", line 126, in import_module
    return _bootstrap._gcd_import(name[level:], package, level)
  File "<frozen importlib._bootstrap>", line 1050, in _gcd_import
  File "<frozen importlib._bootstrap>", line 1027, in _find_and_load
  File "<frozen importlib._bootstrap>", line 1006, in _find_and_load_unlocked
  File "<frozen importlib._bootstrap>", line 688, in _load_unlocked
  File "<frozen importlib._bootstrap_external>", line 883, in exec_module
  File "<frozen importlib._bootstrap>", line 241, in _call_with_frames_removed
  File "/home/student/DCBS/itapps/urls.py", line 19, in <module>
    from users import views
  File "/home/student/DCBS/users/views.py", line 4, in <module>
    from .forms import UserRegisterForm
  File "/home/student/DCBS/users/forms.py", line 4, in <module>
    from .models import Profile
ImportError: cannot import name 'Profile' from 'users.models' (/home/student/DCBS/users/models.py)
/home/student/DCBS/users/forms.py changed, reloading.
Performing system checks...

Watching for file changes with StatReloader
Exception in thread django-main-thread:
Traceback (most recent call last):
  File "/home/student/.local/lib/python3.10/site-packages/django/core/checks/urls.py", line 136, in check_custom_error_handlers
    handler = resolver.resolve_error_handler(status_code)
  File "/home/student/.local/lib/python3.10/site-packages/django/urls/resolvers.py", line 732, in resolve_error_handler
    callback = getattr(self.urlconf_module, "handler%s" % view_type, None)
  File "/home/student/.local/lib/python3.10/site-packages/django/utils/functional.py", line 47, in __get__
    res = instance.__dict__[self.name] = self.func(instance)
  File "/home/student/.local/lib/python3.10/site-packages/django/urls/resolvers.py", line 711, in urlconf_module
    return import_module(self.urlconf_name)
  File "/usr/lib/python3.10/importlib/__init__.py", line 126, in import_module
    return _bootstrap._gcd_import(name[level:], package, level)
  File "<frozen importlib._bootstrap>", line 1050, in _gcd_import
  File "<frozen importlib._bootstrap>", line 1027, in _find_and_load
  File "<frozen importlib._bootstrap>", line 1006, in _find_and_load_unlocked
  File "<frozen importlib._bootstrap>", line 688, in _load_unlocked
  File "<frozen importlib._bootstrap_external>", line 883, in exec_module
  File "<frozen importlib._bootstrap>", line 241, in _call_with_frames_removed
  File "/home/student/DCBS/itapps/urls.py", line 19, in <module>
    from users import views
  File "/home/student/DCBS/users/views.py", line 4, in <module>
    from .forms import UserRegisterForm
  File "/home/student/DCBS/users/forms.py", line 4, in <module>
    from .models import Profile
ImportError: cannot import name 'Profile' from 'users.models' (/home/student/DCBS/users/models.py)

During handling of the above exception, another exception occurred:

Traceback (most recent call last):
  File "/usr/lib/python3.10/threading.py", line 1016, in _bootstrap_inner
    self.run()
  File "/usr/lib/python3.10/threading.py", line 953, in run
    self._target(*self._args, **self._kwargs)
  File "/home/student/.local/lib/python3.10/site-packages/django/utils/autoreload.py", line 64, in wrapper
    fn(*args, **kwargs)
  File "/home/student/.local/lib/python3.10/site-packages/django/core/management/commands/runserver.py", line 134, in inner_run
    self.check(display_num_errors=True)
  File "/home/student/.local/lib/python3.10/site-packages/django/core/management/base.py", line 486, in check
    all_issues = checks.run_checks(
  File "/home/student/.local/lib/python3.10/site-packages/django/core/checks/registry.py", line 88, in run_checks
    new_errors = check(app_configs=app_configs, databases=databases)
  File "/home/student/.local/lib/python3.10/site-packages/django/core/checks/urls.py", line 138, in check_custom_error_handlers
    path = getattr(resolver.urlconf_module, "handler%s" % status_code)
  File "/home/student/.local/lib/python3.10/site-packages/django/utils/functional.py", line 47, in __get__
    res = instance.__dict__[self.name] = self.func(instance)
  File "/home/student/.local/lib/python3.10/site-packages/django/urls/resolvers.py", line 711, in urlconf_module
    return import_module(self.urlconf_name)
  File "/usr/lib/python3.10/importlib/__init__.py", line 126, in import_module
    return _bootstrap._gcd_import(name[level:], package, level)
  File "<frozen importlib._bootstrap>", line 1050, in _gcd_import
  File "<frozen importlib._bootstrap>", line 1027, in _find_and_load
  File "<frozen importlib._bootstrap>", line 1006, in _find_and_load_unlocked
  File "<frozen importlib._bootstrap>", line 688, in _load_unlocked
  File "<frozen importlib._bootstrap_external>", line 883, in exec_module
  File "<frozen importlib._bootstrap>", line 241, in _call_with_frames_removed
  File "/home/student/DCBS/itapps/urls.py", line 19, in <module>
    from users import views
  File "/home/student/DCBS/users/views.py", line 4, in <module>
    from .forms import UserRegisterForm
  File "/home/student/DCBS/users/forms.py", line 4, in <module>
    from .models import Profile
ImportError: cannot import name 'Profile' from 'users.models' (/home/student/DCBS/users/models.py)
/home/student/DCBS/users/admin.py changed, reloading.
Performing system checks...

Watching for file changes with StatReloader
Exception in thread django-main-thread:
Traceback (most recent call last):
  File "/usr/lib/python3.10/threading.py", line 1016, in _bootstrap_inner
    self.run()
  File "/usr/lib/python3.10/threading.py", line 953, in run
    self._target(*self._args, **self._kwargs)
  File "/home/student/.local/lib/python3.10/site-packages/django/utils/autoreload.py", line 64, in wrapper
    fn(*args, **kwargs)
  File "/home/student/.local/lib/python3.10/site-packages/django/core/management/commands/runserver.py", line 126, in inner_run
    autoreload.raise_last_exception()
  File "/home/student/.local/lib/python3.10/site-packages/django/utils/autoreload.py", line 87, in raise_last_exception
    raise _exception[1]
  File "/home/student/.local/lib/python3.10/site-packages/django/core/management/__init__.py", line 394, in execute
    autoreload.check_errors(django.setup)()
  File "/home/student/.local/lib/python3.10/site-packages/django/utils/autoreload.py", line 64, in wrapper
    fn(*args, **kwargs)
  File "/home/student/.local/lib/python3.10/site-packages/django/__init__.py", line 24, in setup
    apps.populate(settings.INSTALLED_APPS)
  File "/home/student/.local/lib/python3.10/site-packages/django/apps/registry.py", line 124, in populate
    app_config.ready()
  File "/home/student/.local/lib/python3.10/site-packages/django/contrib/admin/apps.py", line 27, in ready
    self.module.autodiscover()
  File "/home/student/.local/lib/python3.10/site-packages/django/contrib/admin/__init__.py", line 52, in autodiscover
    autodiscover_modules("admin", register_to=site)
  File "/home/student/.local/lib/python3.10/site-packages/django/utils/module_loading.py", line 58, in autodiscover_modules
    import_module("%s.%s" % (app_config.name, module_to_search))
  File "/usr/lib/python3.10/importlib/__init__.py", line 126, in import_module
    return _bootstrap._gcd_import(name[level:], package, level)
  File "<frozen importlib._bootstrap>", line 1050, in _gcd_import
  File "<frozen importlib._bootstrap>", line 1027, in _find_and_load
  File "<frozen importlib._bootstrap>", line 1006, in _find_and_load_unlocked
  File "<frozen importlib._bootstrap>", line 688, in _load_unlocked
  File "<frozen importlib._bootstrap_external>", line 883, in exec_module
  File "<frozen importlib._bootstrap>", line 241, in _call_with_frames_removed
  File "/home/student/DCBS/users/admin.py", line 2, in <module>
    from .models import Profile
ImportError: cannot import name 'Profile' from 'users.models' (/home/student/DCBS/users/models.py)
/home/student/DCBS/users/models.py changed, reloading.
Watching for file changes with StatReloader
Exception in thread django-main-thread:
Traceback (most recent call last):
  File "/usr/lib/python3.10/threading.py", line 1016, in _bootstrap_inner
    self.run()
  File "/usr/lib/python3.10/threading.py", line 953, in run
    self._target(*self._args, **self._kwargs)
  File "/home/student/.local/lib/python3.10/site-packages/django/utils/autoreload.py", line 64, in wrapper
    fn(*args, **kwargs)
  File "/home/student/.local/lib/python3.10/site-packages/django/core/management/commands/runserver.py", line 126, in inner_run
    autoreload.raise_last_exception()
  File "/home/student/.local/lib/python3.10/site-packages/django/utils/autoreload.py", line 87, in raise_last_exception
    raise _exception[1]
  File "/home/student/.local/lib/python3.10/site-packages/django/core/management/__init__.py", line 394, in execute
    autoreload.check_errors(django.setup)()
  File "/home/student/.local/lib/python3.10/site-packages/django/utils/autoreload.py", line 64, in wrapper
    fn(*args, **kwargs)
  File "/home/student/.local/lib/python3.10/site-packages/django/__init__.py", line 24, in setup
    apps.populate(settings.INSTALLED_APPS)
  File "/home/student/.local/lib/python3.10/site-packages/django/apps/registry.py", line 116, in populate
    app_config.import_models()
  File "/home/student/.local/lib/python3.10/site-packages/django/apps/config.py", line 269, in import_models
    self.models_module = import_module(models_module_name)
  File "/usr/lib/python3.10/importlib/__init__.py", line 126, in import_module
    return _bootstrap._gcd_import(name[level:], package, level)
  File "<frozen importlib._bootstrap>", line 1050, in _gcd_import
  File "<frozen importlib._bootstrap>", line 1027, in _find_and_load
  File "<frozen importlib._bootstrap>", line 1006, in _find_and_load_unlocked
  File "<frozen importlib._bootstrap>", line 688, in _load_unlocked
  File "<frozen importlib._bootstrap_external>", line 883, in exec_module
  File "<frozen importlib._bootstrap>", line 241, in _call_with_frames_removed
  File "/home/student/DCBS/users/models.py", line 5, in <module>
    S
NameError: name 'S' is not defined
/home/student/DCBS/users/models.py changed, reloading.
Watching for file changes with StatReloader
Exception in thread django-main-thread:
Traceback (most recent call last):
  File "/usr/lib/python3.10/threading.py", line 1016, in _bootstrap_inner
    self.run()
  File "/usr/lib/python3.10/threading.py", line 953, in run
    self._target(*self._args, **self._kwargs)
  File "/home/student/.local/lib/python3.10/site-packages/django/utils/autoreload.py", line 64, in wrapper
    fn(*args, **kwargs)
  File "/home/student/.local/lib/python3.10/site-packages/django/core/management/commands/runserver.py", line 126, in inner_run
    autoreload.raise_last_exception()
  File "/home/student/.local/lib/python3.10/site-packages/django/utils/autoreload.py", line 87, in raise_last_exception
    raise _exception[1]
  File "/home/student/.local/lib/python3.10/site-packages/django/core/management/__init__.py", line 394, in execute
    autoreload.check_errors(django.setup)()
  File "/home/student/.local/lib/python3.10/site-packages/django/utils/autoreload.py", line 64, in wrapper
    fn(*args, **kwargs)
  File "/home/student/.local/lib/python3.10/site-packages/django/__init__.py", line 24, in setup
    apps.populate(settings.INSTALLED_APPS)
  File "/home/student/.local/lib/python3.10/site-packages/django/apps/registry.py", line 124, in populate
    app_config.ready()
  File "/home/student/.local/lib/python3.10/site-packages/django/contrib/admin/apps.py", line 27, in ready
    self.module.autodiscover()
  File "/home/student/.local/lib/python3.10/site-packages/django/contrib/admin/__init__.py", line 52, in autodiscover
    autodiscover_modules("admin", register_to=site)
  File "/home/student/.local/lib/python3.10/site-packages/django/utils/module_loading.py", line 58, in autodiscover_modules
    import_module("%s.%s" % (app_config.name, module_to_search))
  File "/usr/lib/python3.10/importlib/__init__.py", line 126, in import_module
    return _bootstrap._gcd_import(name[level:], package, level)
  File "<frozen importlib._bootstrap>", line 1050, in _gcd_import
  File "<frozen importlib._bootstrap>", line 1027, in _find_and_load
  File "<frozen importlib._bootstrap>", line 1006, in _find_and_load_unlocked
  File "<frozen importlib._bootstrap>", line 688, in _load_unlocked
  File "<frozen importlib._bootstrap_external>", line 883, in exec_module
  File "<frozen importlib._bootstrap>", line 241, in _call_with_frames_removed
  File "/home/student/DCBS/users/admin.py", line 2, in <module>
    from .models import Profile
ImportError: cannot import name 'Profile' from 'users.models' (/home/student/DCBS/users/models.py)
/home/student/DCBS/users/admin.py changed, reloading.
Watching for file changes with StatReloader
Exception in thread django-main-thread:
Traceback (most recent call last):
  File "/usr/lib/python3.10/threading.py", line 1016, in _bootstrap_inner
    self.run()
  File "/usr/lib/python3.10/threading.py", line 953, in run
    self._target(*self._args, **self._kwargs)
  File "/home/student/.local/lib/python3.10/site-packages/django/utils/autoreload.py", line 64, in wrapper
    fn(*args, **kwargs)
  File "/home/student/.local/lib/python3.10/site-packages/django/core/management/commands/runserver.py", line 126, in inner_run
    autoreload.raise_last_exception()
  File "/home/student/.local/lib/python3.10/site-packages/django/utils/autoreload.py", line 87, in raise_last_exception
    raise _exception[1]
  File "/home/student/.local/lib/python3.10/site-packages/django/core/management/__init__.py", line 394, in execute
    autoreload.check_errors(django.setup)()
  File "/home/student/.local/lib/python3.10/site-packages/django/utils/autoreload.py", line 64, in wrapper
    fn(*args, **kwargs)
  File "/home/student/.local/lib/python3.10/site-packages/django/__init__.py", line 24, in setup
    apps.populate(settings.INSTALLED_APPS)
  File "/home/student/.local/lib/python3.10/site-packages/django/apps/registry.py", line 124, in populate
    app_config.ready()
  File "/home/student/.local/lib/python3.10/site-packages/django/contrib/admin/apps.py", line 27, in ready
    self.module.autodiscover()
  File "/home/student/.local/lib/python3.10/site-packages/django/contrib/admin/__init__.py", line 52, in autodiscover
    autodiscover_modules("admin", register_to=site)
  File "/home/student/.local/lib/python3.10/site-packages/django/utils/module_loading.py", line 58, in autodiscover_modules
    import_module("%s.%s" % (app_config.name, module_to_search))
  File "/usr/lib/python3.10/importlib/__init__.py", line 126, in import_module
    return _bootstrap._gcd_import(name[level:], package, level)
  File "<frozen importlib._bootstrap>", line 1050, in _gcd_import
  File "<frozen importlib._bootstrap>", line 1027, in _find_and_load
  File "<frozen importlib._bootstrap>", line 1006, in _find_and_load_unlocked
  File "<frozen importlib._bootstrap>", line 688, in _load_unlocked
  File "<frozen importlib._bootstrap_external>", line 883, in exec_module
  File "<frozen importlib._bootstrap>", line 241, in _call_with_frames_removed
  File "/home/student/DCBS/users/admin.py", line 2, in <module>
    from .models import Profile
ImportError: cannot import name 'Profile' from 'users.models' (/home/student/DCBS/users/models.py)
/home/student/DCBS/users/admin.py changed, reloading.
Watching for file changes with StatReloader
Exception in thread django-main-thread:
Traceback (most recent call last):
  File "/usr/lib/python3.10/threading.py", line 1016, in _bootstrap_inner
    self.run()
  File "/usr/lib/python3.10/threading.py", line 953, in run
    self._target(*self._args, **self._kwargs)
  File "/home/student/.local/lib/python3.10/site-packages/django/utils/autoreload.py", line 64, in wrapper
    fn(*args, **kwargs)
  File "/home/student/.local/lib/python3.10/site-packages/django/core/management/commands/runserver.py", line 126, in inner_run
    autoreload.raise_last_exception()
  File "/home/student/.local/lib/python3.10/site-packages/django/utils/autoreload.py", line 87, in raise_last_exception
    raise _exception[1]
  File "/home/student/.local/lib/python3.10/site-packages/django/core/management/__init__.py", line 394, in execute
    autoreload.check_errors(django.setup)()
  File "/home/student/.local/lib/python3.10/site-packages/django/utils/autoreload.py", line 64, in wrapper
    fn(*args, **kwargs)
  File "/home/student/.local/lib/python3.10/site-packages/django/__init__.py", line 24, in setup
    apps.populate(settings.INSTALLED_APPS)
  File "/home/student/.local/lib/python3.10/site-packages/django/apps/registry.py", line 124, in populate
    app_config.ready()
  File "/home/student/.local/lib/python3.10/site-packages/django/contrib/admin/apps.py", line 27, in ready
    self.module.autodiscover()
  File "/home/student/.local/lib/python3.10/site-packages/django/contrib/admin/__init__.py", line 52, in autodiscover
    autodiscover_modules("admin", register_to=site)
  File "/home/student/.local/lib/python3.10/site-packages/django/utils/module_loading.py", line 58, in autodiscover_modules
    import_module("%s.%s" % (app_config.name, module_to_search))
  File "/usr/lib/python3.10/importlib/__init__.py", line 126, in import_module
    return _bootstrap._gcd_import(name[level:], package, level)
  File "<frozen importlib._bootstrap>", line 1050, in _gcd_import
  File "<frozen importlib._bootstrap>", line 1027, in _find_and_load
  File "<frozen importlib._bootstrap>", line 1006, in _find_and_load_unlocked
  File "<frozen importlib._bootstrap>", line 688, in _load_unlocked
  File "<frozen importlib._bootstrap_external>", line 883, in exec_module
  File "<frozen importlib._bootstrap>", line 241, in _call_with_frames_removed
  File "/home/student/DCBS/users/admin.py", line 2, in <module>
    from .models import Profile
ImportError: cannot import name 'Profile' from 'users.models' (/home/student/DCBS/users/models.py)
/home/student/DCBS/users/admin.py changed, reloading.
Watching for file changes with StatReloader
Exception in thread django-main-thread:
Traceback (most recent call last):
  File "/usr/lib/python3.10/threading.py", line 1016, in _bootstrap_inner
    self.run()
  File "/usr/lib/python3.10/threading.py", line 953, in run
    self._target(*self._args, **self._kwargs)
  File "/home/student/.local/lib/python3.10/site-packages/django/utils/autoreload.py", line 64, in wrapper
    fn(*args, **kwargs)
  File "/home/student/.local/lib/python3.10/site-packages/django/core/management/commands/runserver.py", line 126, in inner_run
    autoreload.raise_last_exception()
  File "/home/student/.local/lib/python3.10/site-packages/django/utils/autoreload.py", line 87, in raise_last_exception
    raise _exception[1]
  File "/home/student/.local/lib/python3.10/site-packages/django/core/management/__init__.py", line 394, in execute
    autoreload.check_errors(django.setup)()
  File "/home/student/.local/lib/python3.10/site-packages/django/utils/autoreload.py", line 64, in wrapper
    fn(*args, **kwargs)
  File "/home/student/.local/lib/python3.10/site-packages/django/__init__.py", line 24, in setup
    apps.populate(settings.INSTALLED_APPS)
  File "/home/student/.local/lib/python3.10/site-packages/django/apps/registry.py", line 124, in populate
    app_config.ready()
  File "/home/student/.local/lib/python3.10/site-packages/django/contrib/admin/apps.py", line 27, in ready
    self.module.autodiscover()
  File "/home/student/.local/lib/python3.10/site-packages/django/contrib/admin/__init__.py", line 52, in autodiscover
    autodiscover_modules("admin", register_to=site)
  File "/home/student/.local/lib/python3.10/site-packages/django/utils/module_loading.py", line 58, in autodiscover_modules
    import_module("%s.%s" % (app_config.name, module_to_search))
  File "/usr/lib/python3.10/importlib/__init__.py", line 126, in import_module
    return _bootstrap._gcd_import(name[level:], package, level)
  File "<frozen importlib._bootstrap>", line 1050, in _gcd_import
  File "<frozen importlib._bootstrap>", line 1027, in _find_and_load
  File "<frozen importlib._bootstrap>", line 1006, in _find_and_load_unlocked
  File "<frozen importlib._bootstrap>", line 688, in _load_unlocked
  File "<frozen importlib._bootstrap_external>", line 883, in exec_module
  File "<frozen importlib._bootstrap>", line 241, in _call_with_frames_removed
  File "/home/student/DCBS/users/admin.py", line 2, in <module>
    from .models import Profile
ImportError: cannot import name 'Profile' from 'users.models' (/home/student/DCBS/users/models.py)
/home/student/DCBS/users/admin.py changed, reloading.
Watching for file changes with StatReloader
Exception in thread django-main-thread:
Traceback (most recent call last):
  File "/usr/lib/python3.10/threading.py", line 1016, in _bootstrap_inner
    self.run()
  File "/usr/lib/python3.10/threading.py", line 953, in run
    self._target(*self._args, **self._kwargs)
  File "/home/student/.local/lib/python3.10/site-packages/django/utils/autoreload.py", line 64, in wrapper
    fn(*args, **kwargs)
  File "/home/student/.local/lib/python3.10/site-packages/django/core/management/commands/runserver.py", line 126, in inner_run
    autoreload.raise_last_exception()
  File "/home/student/.local/lib/python3.10/site-packages/django/utils/autoreload.py", line 87, in raise_last_exception
    raise _exception[1]
  File "/home/student/.local/lib/python3.10/site-packages/django/core/management/__init__.py", line 394, in execute
    autoreload.check_errors(django.setup)()
  File "/home/student/.local/lib/python3.10/site-packages/django/utils/autoreload.py", line 64, in wrapper
    fn(*args, **kwargs)
  File "/home/student/.local/lib/python3.10/site-packages/django/__init__.py", line 24, in setup
    apps.populate(settings.INSTALLED_APPS)
  File "/home/student/.local/lib/python3.10/site-packages/django/apps/registry.py", line 124, in populate
    app_config.ready()
  File "/home/student/.local/lib/python3.10/site-packages/django/contrib/admin/apps.py", line 27, in ready
    self.module.autodiscover()
  File "/home/student/.local/lib/python3.10/site-packages/django/contrib/admin/__init__.py", line 52, in autodiscover
    autodiscover_modules("admin", register_to=site)
  File "/home/student/.local/lib/python3.10/site-packages/django/utils/module_loading.py", line 58, in autodiscover_modules
    import_module("%s.%s" % (app_config.name, module_to_search))
  File "/usr/lib/python3.10/importlib/__init__.py", line 126, in import_module
    return _bootstrap._gcd_import(name[level:], package, level)
  File "<frozen importlib._bootstrap>", line 1050, in _gcd_import
  File "<frozen importlib._bootstrap>", line 1027, in _find_and_load
  File "<frozen importlib._bootstrap>", line 1006, in _find_and_load_unlocked
  File "<frozen importlib._bootstrap>", line 688, in _load_unlocked
  File "<frozen importlib._bootstrap_external>", line 883, in exec_module
  File "<frozen importlib._bootstrap>", line 241, in _call_with_frames_removed
  File "/home/student/DCBS/users/admin.py", line 2, in <module>
    from .models import Profile
ImportError: cannot import name 'Profile' from 'users.models' (/home/student/DCBS/users/models.py)
/home/student/DCBS/users/admin.py changed, reloading.
Watching for file changes with StatReloader
Exception in thread django-main-thread:
Traceback (most recent call last):
  File "/usr/lib/python3.10/threading.py", line 1016, in _bootstrap_inner
    self.run()
  File "/usr/lib/python3.10/threading.py", line 953, in run
    self._target(*self._args, **self._kwargs)
  File "/home/student/.local/lib/python3.10/site-packages/django/utils/autoreload.py", line 64, in wrapper
    fn(*args, **kwargs)
  File "/home/student/.local/lib/python3.10/site-packages/django/core/management/commands/runserver.py", line 126, in inner_run
    autoreload.raise_last_exception()
  File "/home/student/.local/lib/python3.10/site-packages/django/utils/autoreload.py", line 87, in raise_last_exception
    raise _exception[1]
  File "/home/student/.local/lib/python3.10/site-packages/django/core/management/__init__.py", line 394, in execute
    autoreload.check_errors(django.setup)()
  File "/home/student/.local/lib/python3.10/site-packages/django/utils/autoreload.py", line 64, in wrapper
    fn(*args, **kwargs)
  File "/home/student/.local/lib/python3.10/site-packages/django/__init__.py", line 24, in setup
    apps.populate(settings.INSTALLED_APPS)
  File "/home/student/.local/lib/python3.10/site-packages/django/apps/registry.py", line 124, in populate
    app_config.ready()
  File "/home/student/.local/lib/python3.10/site-packages/django/contrib/admin/apps.py", line 27, in ready
    self.module.autodiscover()
  File "/home/student/.local/lib/python3.10/site-packages/django/contrib/admin/__init__.py", line 52, in autodiscover
    autodiscover_modules("admin", register_to=site)
  File "/home/student/.local/lib/python3.10/site-packages/django/utils/module_loading.py", line 58, in autodiscover_modules
    import_module("%s.%s" % (app_config.name, module_to_search))
  File "/usr/lib/python3.10/importlib/__init__.py", line 126, in import_module
    return _bootstrap._gcd_import(name[level:], package, level)
  File "<frozen importlib._bootstrap>", line 1050, in _gcd_import
  File "<frozen importlib._bootstrap>", line 1027, in _find_and_load
  File "<frozen importlib._bootstrap>", line 1006, in _find_and_load_unlocked
  File "<frozen importlib._bootstrap>", line 688, in _load_unlocked
  File "<frozen importlib._bootstrap_external>", line 883, in exec_module
  File "<frozen importlib._bootstrap>", line 241, in _call_with_frames_removed
  File "/home/student/DCBS/users/admin.py", line 2, in <module>
    from .models import Profile
ImportError: cannot import name 'Profile' from 'users.models' (/home/student/DCBS/users/models.py)
/home/student/DCBS/users/admin.py changed, reloading.
Watching for file changes with StatReloader
Exception in thread django-main-thread:
Traceback (most recent call last):
  File "/usr/lib/python3.10/threading.py", line 1016, in _bootstrap_inner
    self.run()
  File "/usr/lib/python3.10/threading.py", line 953, in run
    self._target(*self._args, **self._kwargs)
  File "/home/student/.local/lib/python3.10/site-packages/django/utils/autoreload.py", line 64, in wrapper
    fn(*args, **kwargs)
  File "/home/student/.local/lib/python3.10/site-packages/django/core/management/commands/runserver.py", line 126, in inner_run
    autoreload.raise_last_exception()
  File "/home/student/.local/lib/python3.10/site-packages/django/utils/autoreload.py", line 87, in raise_last_exception
    raise _exception[1]
  File "/home/student/.local/lib/python3.10/site-packages/django/core/management/__init__.py", line 394, in execute
    autoreload.check_errors(django.setup)()
  File "/home/student/.local/lib/python3.10/site-packages/django/utils/autoreload.py", line 64, in wrapper
    fn(*args, **kwargs)
  File "/home/student/.local/lib/python3.10/site-packages/django/__init__.py", line 24, in setup
    apps.populate(settings.INSTALLED_APPS)
  File "/home/student/.local/lib/python3.10/site-packages/django/apps/registry.py", line 124, in populate
    app_config.ready()
  File "/home/student/.local/lib/python3.10/site-packages/django/contrib/admin/apps.py", line 27, in ready
    self.module.autodiscover()
  File "/home/student/.local/lib/python3.10/site-packages/django/contrib/admin/__init__.py", line 52, in autodiscover
    autodiscover_modules("admin", register_to=site)
  File "/home/student/.local/lib/python3.10/site-packages/django/utils/module_loading.py", line 58, in autodiscover_modules
    import_module("%s.%s" % (app_config.name, module_to_search))
  File "/usr/lib/python3.10/importlib/__init__.py", line 126, in import_module
    return _bootstrap._gcd_import(name[level:], package, level)
  File "<frozen importlib._bootstrap>", line 1050, in _gcd_import
  File "<frozen importlib._bootstrap>", line 1027, in _find_and_load
  File "<frozen importlib._bootstrap>", line 1006, in _find_and_load_unlocked
  File "<frozen importlib._bootstrap>", line 688, in _load_unlocked
  File "<frozen importlib._bootstrap_external>", line 883, in exec_module
  File "<frozen importlib._bootstrap>", line 241, in _call_with_frames_removed
  File "/home/student/DCBS/users/admin.py", line 2, in <module>
    from .models import Profile
ImportError: cannot import name 'Profile' from 'users.models' (/home/student/DCBS/users/models.py)
